Workbook

Sheet Category
B1: Category | C1: Description
A2: 11 | B2: 1 | C2: Cơ điện
A3: 12 | B3: 2 | C3: Điện tử, tự động hóa
A4: 13 | B4: 3 | C4: CNTT, viễn thông
A5: 14 | B5: 4 | C5: Hóa nghiệm
A6: 15 | B6: 5 | C6: Đo lường
A7: 16 | B7: 6 | C7: Môi trường
A8: 17 | B8: 7 | C8: Chữa cháy
A9: 18 | B9: 8 | C9: Nghiêm ngặt an toàn
A10: 19 | B10: 9 | C10: Vận tải
A11: 20 | B11: A | C11: Công nghệ bồn bể
A12: 21 | B12: B | C12: Nhà cửa kiến trúc
A13: 22 | B13: C | C13: Y tế

Sheet OBject Type
A1: Category | B1: Description | C1: ObjectType | D1: Object type text
A2: =VLOOKUP(VALUE(LEFT($C2,2)),Category!$A$2:$C$13,2,FALSE) -> 1 | B2: =VLOOKUP(VALUE(LEFT($C2,2)),Category!$A$2:$C$13,3,FALSE) -> Cơ điện | C2: 1101 | D2: Thiết bị gia nhiệt
A3: =VLOOKUP(VALUE(LEFT($C3,2)),Category!$A$2:$C$13,2,FALSE) -> 1 | B3: =VLOOKUP(VALUE(LEFT($C3,2)),Category!$A$2:$C$13,3,FALSE) -> Cơ điện | C3: 1102 | D3: Nồi hơi
A4: =VLOOKUP(VALUE(LEFT($C4,2)),Category!$A$2:$C$13,2,FALSE) -> 1 | B4: =VLOOKUP(VALUE(LEFT($C4,2)),Category!$A$2:$C$13,3,FALSE) -> Cơ điện | C4: 1103 | D4: Máy nén khí
A5: =VLOOKUP(VALUE(LEFT($C5,2)),Category!$A$2:$C$13,2,FALSE) -> 1 | B5: =VLOOKUP(VALUE(LEFT($C5,2)),Category!$A$2:$C$13,3,FALSE) -> Cơ điện | C5: 1104 | D5: MPĐ xoay chiều
A6: =VLOOKUP(VALUE(LEFT($C6,2)),Category!$A$2:$C$13,2,FALSE) -> 1 | B6: =VLOOKUP(VALUE(LEFT($C6,2)),Category!$A$2:$C$13,3,FALSE) -> Cơ điện | C6: 1105 | D6: Máy biến áp điện
A7: =VLOOKUP(VALUE(LEFT($C7,2)),Category!$A$2:$C$13,2,FALSE) -> 1 | B7: =VLOOKUP(VALUE(LEFT($C7,2)),Category!$A$2:$C$13,3,FALSE) -> Cơ điện | C7: 1106 | D7: Máy ổn áp
A8: =VLOOKUP(VALUE(LEFT($C8,2)),Category!$A$2:$C$13,2,FALSE) -> 1 | B8: =VLOOKUP(VALUE(LEFT($C8,2)),Category!$A$2:$C$13,3,FALSE) -> Cơ điện | C8: 1107 | D8: Bộ lưu điện (UPS)
A9: =VLOOKUP(VALUE(LEFT($C9,2)),Category!$A$2:$C$13,2,FALSE) -> 1 | B9: =VLOOKUP(VALUE(LEFT($C9,2)),Category!$A$2:$C$13,3,FALSE) -> Cơ điện | C9: 1108 | D9: Tủ tụ bù điện
A10: =VLOOKUP(VALUE(LEFT($C10,2)),Category!$A$2:$C$13,2,FALSE) -> 1 | B10: =VLOOKUP(VALUE(LEFT($C10,2)),Category!$A$2:$C$13,3,FALSE) -> Cơ điện | C10: 1109 | D10: Hệ thống điện
A11: =VLOOKUP(VALUE(LEFT($C11,2)),Category!$A$2:$C$13,2,FALSE) -> 1 | B11: =VLOOKUP(VALUE(LEFT($C11,2)),Category!$A$2:$C$13,3,FALSE) -> Cơ điện | C11: 1110 | D11: Máy tiện
A12: =VLOOKUP(VALUE(LEFT($C12,2)),Category!$A$2:$C$13,2,FALSE) -> 1 | B12: =VLOOKUP(VALUE(LEFT($C12,2)),Category!$A$2:$C$13,3,FALSE) -> Cơ điện | C12: 1111 | D12: Máy khoan
A13: =VLOOKUP(VALUE(LEFT($C13,2)),Category!$A$2:$C$13,2,FALSE) -> 1 | B13: =VLOOKUP(VALUE(LEFT($C13,2)),Category!$A$2:$C$13,3,FALSE) -> Cơ điện | C13: 1112 | D13: Máy doa
... A243: =VLOOKUP(VALUE(LEFT($C243,2)),Category!$A$2:$C$13,2,FALSE) -> C | B243: =VLOOKUP(VALUE(LEFT($C243,2)),Category!$A$2:$C$13,3,FALSE) -> Y tế | C243: 2299 | D243: Thiết bị y tế khác

Sheet dm_objectClass
A1: Category | B1: Description | C1: ObjectType | D1: Object type text | E1: Class | F1: Language | G1: Class description
A2: 1 | B2: Cơ điện | C2: 1103 | D2: Máy nén khí | E2: 110301 | F2: EN | G2: ĐỘNG CƠ ĐIỆN | H2: =LEN(E2) -> 6
A3: 1 | B3: Cơ điện | C3: 1103 | D3: Máy nén khí | E3: 11030101 | F3: EN | G3: ĐỘNG CƠ ĐIỆN | H3: =LEN(E3) -> 8
A4: 1 | B4: Cơ điện | C4: 1103 | D4: Máy nén khí | E4: 11030102 | F4: EN | G4: ĐẦU NÉN KHÍ | H4: =LEN(E4) -> 8
A5: 1 | B5: Cơ điện | C5: 1103 | D5: Máy nén khí | E5: 110302 | F5: EN | G5: ĐỘNG CƠ NỔ | H5: =LEN(E5) -> 6
A6: 1 | B6: Cơ điện | C6: 1103 | D6: Máy nén khí | E6: 11030201 | F6: EN | G6: ĐỘNG CƠ NỔ | H6: =LEN(E6) -> 8
A7: 1 | B7: Cơ điện | C7: 1103 | D7: Máy nén khí | E7: 11030202 | F7: EN | G7: ĐẦU NÉN KHÍ | H7: =LEN(E7) -> 8
A8: 1 | B8: Cơ điện | C8: 1104 | D8: MPĐ xoay chiều | E8: 110401 | F8: EN | G8: ĐỘNG CƠ NỔ | H8: =LEN(E8) -> 6
A9: 1 | B9: Cơ điện | C9: 1104 | D9: MPĐ xoay chiều | E9: 11040101 | F9: EN | G9: ĐỘNG CƠ NỔ | H9: =LEN(E9) -> 8
A10: 1 | B10: Cơ điện | C10: 1104 | D10: MPĐ xoay chiều | E10: 11040102 | F10: EN | G10: ĐẦU PHÁT ĐIỆN | H10: =LEN(E10) -> 8
A11: 1 | B11: Cơ điện | C11: 1105 | D11: Máy biến áp điện | E11: 110501 | F11: EN | G11: MÁY BIẾN ÁP ĐIỆN | H11: =LEN(E11) -> 6
A12: 1 | B12: Cơ điện | C12: 1105 | D12: Máy biến áp điện | E12: 11050101 | F12: EN | G12: MÁY BIẾN ÁP ĐIỆN | H12: =LEN(E12) -> 8
A13: 1 | B13: Cơ điện | C13: 1106 | D13: Máy ổn áp | E13: 110601 | F13: EN | G13: MÁY ỔN ÁP | H13: =LEN(E13) -> 6
... A638: 9 | B638: Vận tải | C638: 1916 | D638: Xà lan | E638: 19160103 | F638: EN | G638: CẦN CẨU UNIC: | H638: =LEN(E638) -> 8
A639: 9 | B639: Vận tải | C639: 1916 | D639: Xà lan | E639: 191602 | F639: EN | G639: XÀ LAN CHỞ XĂNG DẦU KHÔNG TỰ HÀNH TRÊN S | H639: =LEN(E639) -> 6 | I639: caapnhat tên
A640: 9 | B640: Vận tải | C640: 1916 | D640: Xà lan | E640: 19160201 | F640: EN | G640: THÂN TÀU: VỎ THÉP | H640: =LEN(E640) -> 8
A641: 9 | B641: Vận tải | C641: 1916 | D641: Xà lan | E641: 19160202 | F641: EN | G641: MÁY BƠM- ĐỘNG CƠ NỔ | H641: =LEN(E641) -> 8
A642: 9 | B642: Vận tải | C642: 1916 | D642: Xà lan | E642: 19160203 | F642: EN | G642: MÁY BƠM- ĐẦU BƠM | H642: =LEN(E642) -> 8
A643: 9 | B643: Vận tải | C643: 1916 | D643: Xà lan | E643: 191603 | F643: EN | G643: XÀ LAN CHỞ XĂNG DẦU PHA SÔNG BIỂN | H643: =LEN(E643) -> 6
A644: 9 | B644: Vận tải | C644: 1916 | D644: Xà lan | E644: 19160301 | F644: EN | G644: XÀ LAN CHỞ XĂNG DẦU PHA SÔNG BIỂN | H644: =LEN(E644) -> 8
A645: 9 | B645: Vận tải | C645: 1916 | D645: Xà lan | E645: 191604 | F645: EN | G645: XA LAN CHỞ HÀNG KHÁC TRÊN SÔNG | H645: =LEN(E645) -> 6
A646: 9 | B646: Vận tải | C646: 1916 | D646: Xà lan | E646: 19160401 | F646: EN | G646: XA LAN CHỞ HÀNG KHÁC TRÊN SÔNG | H646: =LEN(E646) -> 8
A647: 9 | B647: Vận tải | C647: 1917 | D647: Ca nô | E647: 191701 | F647: EN | G647: CA NÔ | H647: =LEN(E647) -> 6
A648: 9 | B648: Vận tải | C648: 1917 | D648: Ca nô | E648: 19170101 | F648: EN | G648: THÂN TÀU: VỎ COMPOSIT | H648: =LEN(E648) -> 8
A649: 9 | B649: Vận tải | C649: 1917 | D649: Ca nô | E649: 19170102 | F649: EN | G649: MÁY CHÍNH | H649: =LEN(E649) -> 8
A650: 9 | B650: Vận tải | C650: 1918 | D650: Xe máy, xe đạp | E650: 191801 | F650: EN | G650: XE ĐẠP | H650: =LEN(E650) -> 6
A651: 9 | B651: Vận tải | C651: 1918 | D651: Xe máy, xe đạp | E651: 19180101 | F651: EN | G651: XE ĐẠP | H651: =LEN(E651) -> 8
... A668: 9 | B668: Vận tải | C668: 1999 | D668: PTVT khác | E668: 19990101 | F668: EN | G668: PTVT KHÁC | H668: =LEN(E668) -> 8
A669: A | B669: Công nghệ bồn bể | C669: 2001 | D669: Hệ thống công nghệ | E669: 200101 | F669: EN | G669: CÔNG NGHỆ XĂNG DẦU | H669: =LEN(E669) -> 6
A670: A | B670: Công nghệ bồn bể | C670: 2001 | D670: Hệ thống công nghệ | E670: 20010101 | F670: EN | G670: CÔNG NGHỆ XĂNG DẦU | H670: =LEN(E670) -> 8
A671: A | B671: Công nghệ bồn bể | C671: 2001 | D671: Hệ thống công nghệ | E671: 200102 | F671: EN | G671: CÔNG NGHỆ NƯỚC SINH HOẠT | H671: =LEN(E671) -> 6
A672: A | B672: Công nghệ bồn bể | C672: 2001 | D672: Hệ thống công nghệ | E672: 20010201 | F672: EN | G672: CÔNG NGHỆ NƯỚC SINH HOẠT | H672: =LEN(E672) -> 8
A673: A | B673: Công nghệ bồn bể | C673: 2001 | D673: Hệ thống công nghệ | E673: 200103 | F673: EN | G673: CÔNG NGHỆ PCCC | H673: =LEN(E673) -> 6
A674: A | B674: Công nghệ bồn bể | C674: 2001 | D674: Hệ thống công nghệ | E674: 20010301 | F674: EN | G674: CÔNG NGHỆ PCCC | H674: =LEN(E674) -> 8
A675: A | B675: Công nghệ bồn bể | C675: 2001 | D675: Hệ thống công nghệ | E675: 200104 | F675: EN | G675: CÔNG NGHỆ XẢ KÍN | H675: =LEN(E675) -> 6
A676: A | B676: Công nghệ bồn bể | C676: 2001 | D676: Hệ thống công nghệ | E676: 20010401 | F676: EN | G676: CÔNG NGHỆ XẢ KÍN | H676: =LEN(E676) -> 8
A677: A | B677: Công nghệ bồn bể | C677: 2002 | D677: Đường ống xăng dầu | E677: 200201 | F677: EN | G677: ỐNG THÉP | H677: =LEN(E677) -> 6
A678: A | B678: Công nghệ bồn bể | C678: 2002 | D678: Đường ống xăng dầu | E678: 20020101 | F678: EN | G678: ỐNG THÉP | H678: =LEN(E678) -> 8
A679: A | B679: Công nghệ bồn bể | C679: 2002 | D679: Đường ống xăng dầu | E679: 200202 | F679: EN | G679: ỐNG INOX | H679: =LEN(E679) -> 6
A680: A | B680: Công nghệ bồn bể | C680: 2002 | D680: Đường ống xăng dầu | E680: 20020201 | F680: EN | G680: ỐNG INOX | H680: =LEN(E680) -> 8
...

Sheet Sheet2
A1: 2 | B1: Điện tử, tự động hóa | C1: 1207 | D1: HT đo bể tự động | E1: 120701 | F1: EN | G1: HT ĐO BỂ TỰ ĐỘNG | H1: tên class Update
E2: 12070101 | F2: EN | G2: HT ĐO BỂ TỰ ĐỘNG
E3: class | G3: tên class | I3: Ghi chú
E4: 12070102 | F4: EN | G4: BỘ THU TÍN HIỆU- KIỂU RADAR | I4: xóa
E5: 120702 | F5: EN | G5: KIỂU PHAO NỔI | I5: xóa
E6: 12070201 | F6: EN | G6: BỘ HIỂN THỊ- KIỂU PHAO NỔI | I6: xóa
E7: 12070202 | F7: EN | G7: BỘ THU TÍN HIỆU- KIỂU PHAO NỔI | I7: xóa
A8: 2 | B8: Điện tử, tự động hóa | C8: 1207 | D8: HT đo bể tự động | E8: 120703 | F8: EN | G8: KIỂU TỪ TÍNH | I8: xóa
E9: 12070301 | F9: EN | G9: BỘ HIỂN THỊ- KIỂU TỪ TÍNH | I9: xóa
E10: 12070302 | F10: EN | G10: BỘ THU TÍN HIỆU- KIỂU TỪ TÍNH | I10: xóa
A11: 2 | B11: Điện tử, tự động hóa | C11: 1209 | D11: Sensor nhiệtđộ | E11: 120902 | F11: EN | G11: SENSOR NHIỆT ĐỘ (XUẤT HÀNG) | I11: xóa
E12: 12090201 | F12: EN | G12: SENSOR NHIỆT ĐỘ (XUẤT HÀNG) | I12: xóa
E15: 191602 | F15: EN | G15: XÀ LAN CHỞ XĂNG DẦU KHÔNG TỰ HÀNH TRÊN S | H15: XÀ LAN CHỞ X/DẦU KHÔNG TỰ HÀNH TRÊN SÔNG | I15: cập nhât tên
